INFO:tornado.access:200 GET /checkid/qpqp (192.168.43.1) 9.71ms
INFO:tornado.access:200 GET /id/qpqp/pass/qpqp/name/%EC%B5%9C%EC%9A%B4%ED%95%99/gender/%EB%82%A8/age/18/email/cwh6272@naver.com (192.168.43.1) 10.71ms
INFO:tornado.access:204 GET /name/%EC%B5%9C%EC%9A%B4%ED%95%AB/email/cwh6272@naver.com (192.168.43.1) 4.80ms
INFO:tornado.access:204 GET /name/%EC%B5%9C%EC%9A%B4%ED%95%AB/email/cwh6272@naver.com (192.168.43.1) 3.79ms
INFO:tornado.general:/Users/HwiRiRic/Documents/seoulhang_server/seoulhang_server/app/apis.py modified; restarting server
INFO:tornado.access:204 GET /name/%EC%B5%9C%EC%9A%B4%ED%95%AB/email/cwh6272@naver.com (192.168.43.1) 6.57ms
INFO:tornado.access:204 GET /name/%EC%B5%9C%EC%9A%B4%ED%95%AB/email/cwh6272@naver.com (192.168.43.1) 4.74ms
INFO:tornado.access:204 GET /name/%EC%B5%9C%EC%9A%B4%ED%95%AB/email/cwh6272@naver.com (192.168.43.1) 4.50ms
INFO:tornado.access:204 GET /name/%EC%B5%9C%EC%9A%B4%ED%95%AB/email/cwh6272@naver.com (192.168.43.1) 4.94ms
ERROR:tornado.application:Uncaught exception GET /name/%EC%B5%9C%EC%9A%B4%ED%95%99/email/cwh6272@naver.com (192.168.43.1)
HTTPServerRequest(protocol='http', host='192.168.43.34:5000', method='GET', uri='/name/%EC%B5%9C%EC%9A%B4%ED%95%99/email/cwh6272@naver.com', version='HTTP/1.1', remote_ip='192.168.43.1', headers={'Connection': 'Keep-Alive', 'User-Agent': 'okhttp/3.3.0', 'Host': '192.168.43.34:5000', 'Accept-Encoding': 'gzip'})
Traceback (most recent call last):
  File "/Library/Frameworks/Python.framework/Versions/3.5/lib/python3.5/site-packages/tornado/web.py", line 1422, in _execute
    result = self.prepare()
  File "/Library/Frameworks/Python.framework/Versions/3.5/lib/python3.5/site-packages/tornado/web.py", line 2681, in prepare
    self.fallback(self.request)
  File "/Library/Frameworks/Python.framework/Versions/3.5/lib/python3.5/site-packages/tornado/wsgi.py", line 277, in __call__
    WSGIContainer.environ(request), start_response)
  File "/Library/Frameworks/Python.framework/Versions/3.5/lib/python3.5/site-packages/flask/app.py", line 1836, in __call__
    return self.wsgi_app(environ, start_response)
  File "/Library/Frameworks/Python.framework/Versions/3.5/lib/python3.5/site-packages/flask/app.py", line 1820, in wsgi_app
    response = self.make_response(self.handle_exception(e))
  File "/Library/Frameworks/Python.framework/Versions/3.5/lib/python3.5/site-packages/flask_restful/__init__.py", line 271, in error_router
    return original_handler(e)
  File "/Library/Frameworks/Python.framework/Versions/3.5/lib/python3.5/site-packages/flask/app.py", line 1403, in handle_exception
    reraise(exc_type, exc_value, tb)
  File "/Library/Frameworks/Python.framework/Versions/3.5/lib/python3.5/site-packages/flask/_compat.py", line 32, in reraise
    raise value.with_traceback(tb)
  File "/Library/Frameworks/Python.framework/Versions/3.5/lib/python3.5/site-packages/flask/app.py", line 1817, in wsgi_app
    response = self.full_dispatch_request()
  File "/Library/Frameworks/Python.framework/Versions/3.5/lib/python3.5/site-packages/flask/app.py", line 1477, in full_dispatch_request
    rv = self.handle_user_exception(e)
  File "/Library/Frameworks/Python.framework/Versions/3.5/lib/python3.5/site-packages/flask_restful/__init__.py", line 271, in error_router
    return original_handler(e)
  File "/Library/Frameworks/Python.framework/Versions/3.5/lib/python3.5/site-packages/flask/app.py", line 1381, in handle_user_exception
    reraise(exc_type, exc_value, tb)
  File "/Library/Frameworks/Python.framework/Versions/3.5/lib/python3.5/site-packages/flask/_compat.py", line 32, in reraise
    raise value.with_traceback(tb)
  File "/Library/Frameworks/Python.framework/Versions/3.5/lib/python3.5/site-packages/flask/app.py", line 1475, in full_dispatch_request
    rv = self.dispatch_request()
  File "/Library/Frameworks/Python.framework/Versions/3.5/lib/python3.5/site-packages/flask/app.py", line 1461, in dispatch_request
    return self.view_functions[rule.endpoint](**req.view_args)
  File "/Library/Frameworks/Python.framework/Versions/3.5/lib/python3.5/site-packages/flask_restful/__init__.py", line 477, in wrapper
    resp = resource(*args, **kwargs)
  File "/Library/Frameworks/Python.framework/Versions/3.5/lib/python3.5/site-packages/flask/views.py", line 84, in view
    return self.dispatch_request(*args, **kwargs)
  File "/Library/Frameworks/Python.framework/Versions/3.5/lib/python3.5/site-packages/flask_restful/__init__.py", line 587, in dispatch_request
    resp = meth(*args, **kwargs)
  File "/Users/HwiRiRic/Documents/seoulhang_server/seoulhang_server/app/apis.py", line 579, in get
    SendMail(data)
  File "/Users/HwiRiRic/Documents/seoulhang_server/seoulhang_server/send_mail.py", line 21, in __init__
    self.send_confirm_mail(data)
  File "/Users/HwiRiRic/Documents/seoulhang_server/seoulhang_server/send_mail.py", line 56, in send_confirm_mail
    title = self.get_email_content(lost)[0]
  File "/Users/HwiRiRic/Documents/seoulhang_server/seoulhang_server/send_mail.py", line 24, in get_email_content
    f = open("app/import/find_"+lost+".txt","rb")
FileNotFoundError: [Errno 2] No such file or directory: 'app/import/find_id.txt'
ERROR:tornado.access:500 GET /name/%EC%B5%9C%EC%9A%B4%ED%95%99/email/cwh6272@naver.com (192.168.43.1) 22.42ms
INFO:tornado.general:/Users/HwiRiRic/Documents/seoulhang_server/seoulhang_server/app/apis.py modified; restarting server
ERROR:tornado.application:Uncaught exception GET /name/%EC%B5%9C%EC%9A%B4%ED%95%99/email/cwh6272@naver.com (192.168.43.1)
HTTPServerRequest(protocol='http', host='192.168.43.34:5000', method='GET', uri='/name/%EC%B5%9C%EC%9A%B4%ED%95%99/email/cwh6272@naver.com', version='HTTP/1.1', remote_ip='192.168.43.1', headers={'Accept-Encoding': 'gzip', 'Host': '192.168.43.34:5000', 'User-Agent': 'okhttp/3.3.0', 'Connection': 'Keep-Alive'})
Traceback (most recent call last):
  File "/Library/Frameworks/Python.framework/Versions/3.5/lib/python3.5/site-packages/tornado/web.py", line 1422, in _execute
    result = self.prepare()
  File "/Library/Frameworks/Python.framework/Versions/3.5/lib/python3.5/site-packages/tornado/web.py", line 2681, in prepare
    self.fallback(self.request)
  File "/Library/Frameworks/Python.framework/Versions/3.5/lib/python3.5/site-packages/tornado/wsgi.py", line 277, in __call__
    WSGIContainer.environ(request), start_response)
  File "/Library/Frameworks/Python.framework/Versions/3.5/lib/python3.5/site-packages/flask/app.py", line 1836, in __call__
    return self.wsgi_app(environ, start_response)
  File "/Library/Frameworks/Python.framework/Versions/3.5/lib/python3.5/site-packages/flask/app.py", line 1820, in wsgi_app
    response = self.make_response(self.handle_exception(e))
  File "/Library/Frameworks/Python.framework/Versions/3.5/lib/python3.5/site-packages/flask_restful/__init__.py", line 271, in error_router
    return original_handler(e)
  File "/Library/Frameworks/Python.framework/Versions/3.5/lib/python3.5/site-packages/flask/app.py", line 1403, in handle_exception
    reraise(exc_type, exc_value, tb)
  File "/Library/Frameworks/Python.framework/Versions/3.5/lib/python3.5/site-packages/flask/_compat.py", line 32, in reraise
    raise value.with_traceback(tb)
  File "/Library/Frameworks/Python.framework/Versions/3.5/lib/python3.5/site-packages/flask/app.py", line 1817, in wsgi_app
    response = self.full_dispatch_request()
  File "/Library/Frameworks/Python.framework/Versions/3.5/lib/python3.5/site-packages/flask/app.py", line 1477, in full_dispatch_request
    rv = self.handle_user_exception(e)
  File "/Library/Frameworks/Python.framework/Versions/3.5/lib/python3.5/site-packages/flask_restful/__init__.py", line 271, in error_router
    return original_handler(e)
  File "/Library/Frameworks/Python.framework/Versions/3.5/lib/python3.5/site-packages/flask/app.py", line 1381, in handle_user_exception
    reraise(exc_type, exc_value, tb)
  File "/Library/Frameworks/Python.framework/Versions/3.5/lib/python3.5/site-packages/flask/_compat.py", line 32, in reraise
    raise value.with_traceback(tb)
  File "/Library/Frameworks/Python.framework/Versions/3.5/lib/python3.5/site-packages/flask/app.py", line 1475, in full_dispatch_request
    rv = self.dispatch_request()
  File "/Library/Frameworks/Python.framework/Versions/3.5/lib/python3.5/site-packages/flask/app.py", line 1461, in dispatch_request
    return self.view_functions[rule.endpoint](**req.view_args)
  File "/Library/Frameworks/Python.framework/Versions/3.5/lib/python3.5/site-packages/flask_restful/__init__.py", line 477, in wrapper
    resp = resource(*args, **kwargs)
  File "/Library/Frameworks/Python.framework/Versions/3.5/lib/python3.5/site-packages/flask/views.py", line 84, in view
    return self.dispatch_request(*args, **kwargs)
  File "/Library/Frameworks/Python.framework/Versions/3.5/lib/python3.5/site-packages/flask_restful/__init__.py", line 587, in dispatch_request
    resp = meth(*args, **kwargs)
  File "/Users/HwiRiRic/Documents/seoulhang_server/seoulhang_server/app/apis.py", line 580, in get
    SendMail(data)
  File "/Users/HwiRiRic/Documents/seoulhang_server/seoulhang_server/send_mail.py", line 21, in __init__
    self.send_confirm_mail(data)
  File "/Users/HwiRiRic/Documents/seoulhang_server/seoulhang_server/send_mail.py", line 56, in send_confirm_mail
    title = self.get_email_content(lost)[0]
  File "/Users/HwiRiRic/Documents/seoulhang_server/seoulhang_server/send_mail.py", line 24, in get_email_content
    f = open("app/import/find_"+lost+".txt","rb")
FileNotFoundError: [Errno 2] No such file or directory: 'app/import/find_id.txt'
ERROR:tornado.access:500 GET /name/%EC%B5%9C%EC%9A%B4%ED%95%99/email/cwh6272@naver.com (192.168.43.1) 10.91ms
ERROR:tornado.application:Uncaught exception GET /name/%EC%B5%9C%EC%9A%B4%ED%95%99/email/cwh6272@naver.com (192.168.43.1)
HTTPServerRequest(protocol='http', host='192.168.43.34:5000', method='GET', uri='/name/%EC%B5%9C%EC%9A%B4%ED%95%99/email/cwh6272@naver.com', version='HTTP/1.1', remote_ip='192.168.43.1', headers={'Accept-Encoding': 'gzip', 'Host': '192.168.43.34:5000', 'User-Agent': 'okhttp/3.3.0', 'Connection': 'Keep-Alive'})
Traceback (most recent call last):
  File "/Library/Frameworks/Python.framework/Versions/3.5/lib/python3.5/site-packages/tornado/web.py", line 1422, in _execute
    result = self.prepare()
  File "/Library/Frameworks/Python.framework/Versions/3.5/lib/python3.5/site-packages/tornado/web.py", line 2681, in prepare
    self.fallback(self.request)
  File "/Library/Frameworks/Python.framework/Versions/3.5/lib/python3.5/site-packages/tornado/wsgi.py", line 277, in __call__
    WSGIContainer.environ(request), start_response)
  File "/Library/Frameworks/Python.framework/Versions/3.5/lib/python3.5/site-packages/flask/app.py", line 1836, in __call__
    return self.wsgi_app(environ, start_response)
  File "/Library/Frameworks/Python.framework/Versions/3.5/lib/python3.5/site-packages/flask/app.py", line 1820, in wsgi_app
    response = self.make_response(self.handle_exception(e))
  File "/Library/Frameworks/Python.framework/Versions/3.5/lib/python3.5/site-packages/flask_restful/__init__.py", line 271, in error_router
    return original_handler(e)
  File "/Library/Frameworks/Python.framework/Versions/3.5/lib/python3.5/site-packages/flask/app.py", line 1403, in handle_exception
    reraise(exc_type, exc_value, tb)
  File "/Library/Frameworks/Python.framework/Versions/3.5/lib/python3.5/site-packages/flask/_compat.py", line 32, in reraise
    raise value.with_traceback(tb)
  File "/Library/Frameworks/Python.framework/Versions/3.5/lib/python3.5/site-packages/flask/app.py", line 1817, in wsgi_app
    response = self.full_dispatch_request()
  File "/Library/Frameworks/Python.framework/Versions/3.5/lib/python3.5/site-packages/flask/app.py", line 1477, in full_dispatch_request
    rv = self.handle_user_exception(e)
  File "/Library/Frameworks/Python.framework/Versions/3.5/lib/python3.5/site-packages/flask_restful/__init__.py", line 271, in error_router
    return original_handler(e)
  File "/Library/Frameworks/Python.framework/Versions/3.5/lib/python3.5/site-packages/flask/app.py", line 1381, in handle_user_exception
    reraise(exc_type, exc_value, tb)
  File "/Library/Frameworks/Python.framework/Versions/3.5/lib/python3.5/site-packages/flask/_compat.py", line 32, in reraise
    raise value.with_traceback(tb)
  File "/Library/Frameworks/Python.framework/Versions/3.5/lib/python3.5/site-packages/flask/app.py", line 1475, in full_dispatch_request
    rv = self.dispatch_request()
  File "/Library/Frameworks/Python.framework/Versions/3.5/lib/python3.5/site-packages/flask/app.py", line 1461, in dispatch_request
    return self.view_functions[rule.endpoint](**req.view_args)
  File "/Library/Frameworks/Python.framework/Versions/3.5/lib/python3.5/site-packages/flask_restful/__init__.py", line 477, in wrapper
    resp = resource(*args, **kwargs)
  File "/Library/Frameworks/Python.framework/Versions/3.5/lib/python3.5/site-packages/flask/views.py", line 84, in view
    return self.dispatch_request(*args, **kwargs)
  File "/Library/Frameworks/Python.framework/Versions/3.5/lib/python3.5/site-packages/flask_restful/__init__.py", line 587, in dispatch_request
    resp = meth(*args, **kwargs)
  File "/Users/HwiRiRic/Documents/seoulhang_server/seoulhang_server/app/apis.py", line 580, in get
    SendMail(data)
  File "/Users/HwiRiRic/Documents/seoulhang_server/seoulhang_server/send_mail.py", line 21, in __init__
    self.send_confirm_mail(data)
  File "/Users/HwiRiRic/Documents/seoulhang_server/seoulhang_server/send_mail.py", line 56, in send_confirm_mail
    title = self.get_email_content(lost)[0]
  File "/Users/HwiRiRic/Documents/seoulhang_server/seoulhang_server/send_mail.py", line 24, in get_email_content
    f = open("app/import/find_"+lost+".txt","rb")
FileNotFoundError: [Errno 2] No such file or directory: 'app/import/find_id.txt'
ERROR:tornado.access:500 GET /name/%EC%B5%9C%EC%9A%B4%ED%95%99/email/cwh6272@naver.com (192.168.43.1) 6.34ms
INFO:tornado.general:/Users/HwiRiRic/Documents/seoulhang_server/seoulhang_server/app/apis.py modified; restarting server
ERROR:tornado.application:Uncaught exception GET /name/%EC%B5%9C%EC%9A%B4%ED%95%99/email/cwh6272@naver.com (192.168.43.1)
HTTPServerRequest(protocol='http', host='192.168.43.34:5000', method='GET', uri='/name/%EC%B5%9C%EC%9A%B4%ED%95%99/email/cwh6272@naver.com', version='HTTP/1.1', remote_ip='192.168.43.1', headers={'Host': '192.168.43.34:5000', 'Connection': 'Keep-Alive', 'Accept-Encoding': 'gzip', 'User-Agent': 'okhttp/3.3.0'})
Traceback (most recent call last):
  File "/Library/Frameworks/Python.framework/Versions/3.5/lib/python3.5/site-packages/tornado/web.py", line 1422, in _execute
    result = self.prepare()
  File "/Library/Frameworks/Python.framework/Versions/3.5/lib/python3.5/site-packages/tornado/web.py", line 2681, in prepare
    self.fallback(self.request)
  File "/Library/Frameworks/Python.framework/Versions/3.5/lib/python3.5/site-packages/tornado/wsgi.py", line 277, in __call__
    WSGIContainer.environ(request), start_response)
  File "/Library/Frameworks/Python.framework/Versions/3.5/lib/python3.5/site-packages/flask/app.py", line 1836, in __call__
    return self.wsgi_app(environ, start_response)
  File "/Library/Frameworks/Python.framework/Versions/3.5/lib/python3.5/site-packages/flask/app.py", line 1820, in wsgi_app
    response = self.make_response(self.handle_exception(e))
  File "/Library/Frameworks/Python.framework/Versions/3.5/lib/python3.5/site-packages/flask_restful/__init__.py", line 271, in error_router
    return original_handler(e)
  File "/Library/Frameworks/Python.framework/Versions/3.5/lib/python3.5/site-packages/flask/app.py", line 1403, in handle_exception
    reraise(exc_type, exc_value, tb)
  File "/Library/Frameworks/Python.framework/Versions/3.5/lib/python3.5/site-packages/flask/_compat.py", line 32, in reraise
    raise value.with_traceback(tb)
  File "/Library/Frameworks/Python.framework/Versions/3.5/lib/python3.5/site-packages/flask/app.py", line 1817, in wsgi_app
    response = self.full_dispatch_request()
  File "/Library/Frameworks/Python.framework/Versions/3.5/lib/python3.5/site-packages/flask/app.py", line 1477, in full_dispatch_request
    rv = self.handle_user_exception(e)
  File "/Library/Frameworks/Python.framework/Versions/3.5/lib/python3.5/site-packages/flask_restful/__init__.py", line 271, in error_router
    return original_handler(e)
  File "/Library/Frameworks/Python.framework/Versions/3.5/lib/python3.5/site-packages/flask/app.py", line 1381, in handle_user_exception
    reraise(exc_type, exc_value, tb)
  File "/Library/Frameworks/Python.framework/Versions/3.5/lib/python3.5/site-packages/flask/_compat.py", line 32, in reraise
    raise value.with_traceback(tb)
  File "/Library/Frameworks/Python.framework/Versions/3.5/lib/python3.5/site-packages/flask/app.py", line 1475, in full_dispatch_request
    rv = self.dispatch_request()
  File "/Library/Frameworks/Python.framework/Versions/3.5/lib/python3.5/site-packages/flask/app.py", line 1461, in dispatch_request
    return self.view_functions[rule.endpoint](**req.view_args)
  File "/Library/Frameworks/Python.framework/Versions/3.5/lib/python3.5/site-packages/flask_restful/__init__.py", line 477, in wrapper
    resp = resource(*args, **kwargs)
  File "/Library/Frameworks/Python.framework/Versions/3.5/lib/python3.5/site-packages/flask/views.py", line 84, in view
    return self.dispatch_request(*args, **kwargs)
  File "/Library/Frameworks/Python.framework/Versions/3.5/lib/python3.5/site-packages/flask_restful/__init__.py", line 587, in dispatch_request
    resp = meth(*args, **kwargs)
  File "/Users/HwiRiRic/Documents/seoulhang_server/seoulhang_server/app/apis.py", line 581, in get
    SendMail(data)
  File "/Users/HwiRiRic/Documents/seoulhang_server/seoulhang_server/send_mail.py", line 21, in __init__
    self.send_confirm_mail(data)
  File "/Users/HwiRiRic/Documents/seoulhang_server/seoulhang_server/send_mail.py", line 56, in send_confirm_mail
    title = self.get_email_content(lost)[0]
  File "/Users/HwiRiRic/Documents/seoulhang_server/seoulhang_server/send_mail.py", line 24, in get_email_content
    f = open("app/import/find_"+lost+".txt","rb")
FileNotFoundError: [Errno 2] No such file or directory: 'app/import/find_id.txt'
ERROR:tornado.access:500 GET /name/%EC%B5%9C%EC%9A%B4%ED%95%99/email/cwh6272@naver.com (192.168.43.1) 10.98ms
ERROR:tornado.application:Uncaught exception GET /name/%EC%B5%9C%EC%9A%B4%ED%95%99/email/cwh6272@naver.com (192.168.43.1)
HTTPServerRequest(protocol='http', host='192.168.43.34:5000', method='GET', uri='/name/%EC%B5%9C%EC%9A%B4%ED%95%99/email/cwh6272@naver.com', version='HTTP/1.1', remote_ip='192.168.43.1', headers={'Host': '192.168.43.34:5000', 'Connection': 'Keep-Alive', 'Accept-Encoding': 'gzip', 'User-Agent': 'okhttp/3.3.0'})
Traceback (most recent call last):
  File "/Library/Frameworks/Python.framework/Versions/3.5/lib/python3.5/site-packages/tornado/web.py", line 1422, in _execute
    result = self.prepare()
  File "/Library/Frameworks/Python.framework/Versions/3.5/lib/python3.5/site-packages/tornado/web.py", line 2681, in prepare
    self.fallback(self.request)
  File "/Library/Frameworks/Python.framework/Versions/3.5/lib/python3.5/site-packages/tornado/wsgi.py", line 277, in __call__
    WSGIContainer.environ(request), start_response)
  File "/Library/Frameworks/Python.framework/Versions/3.5/lib/python3.5/site-packages/flask/app.py", line 1836, in __call__
    return self.wsgi_app(environ, start_response)
  File "/Library/Frameworks/Python.framework/Versions/3.5/lib/python3.5/site-packages/flask/app.py", line 1820, in wsgi_app
    response = self.make_response(self.handle_exception(e))
  File "/Library/Frameworks/Python.framework/Versions/3.5/lib/python3.5/site-packages/flask_restful/__init__.py", line 271, in error_router
    return original_handler(e)
  File "/Library/Frameworks/Python.framework/Versions/3.5/lib/python3.5/site-packages/flask/app.py", line 1403, in handle_exception
    reraise(exc_type, exc_value, tb)
  File "/Library/Frameworks/Python.framework/Versions/3.5/lib/python3.5/site-packages/flask/_compat.py", line 32, in reraise
    raise value.with_traceback(tb)
  File "/Library/Frameworks/Python.framework/Versions/3.5/lib/python3.5/site-packages/flask/app.py", line 1817, in wsgi_app
    response = self.full_dispatch_request()
  File "/Library/Frameworks/Python.framework/Versions/3.5/lib/python3.5/site-packages/flask/app.py", line 1477, in full_dispatch_request
    rv = self.handle_user_exception(e)
  File "/Library/Frameworks/Python.framework/Versions/3.5/lib/python3.5/site-packages/flask_restful/__init__.py", line 271, in error_router
    return original_handler(e)
  File "/Library/Frameworks/Python.framework/Versions/3.5/lib/python3.5/site-packages/flask/app.py", line 1381, in handle_user_exception
    reraise(exc_type, exc_value, tb)
  File "/Library/Frameworks/Python.framework/Versions/3.5/lib/python3.5/site-packages/flask/_compat.py", line 32, in reraise
    raise value.with_traceback(tb)
  File "/Library/Frameworks/Python.framework/Versions/3.5/lib/python3.5/site-packages/flask/app.py", line 1475, in full_dispatch_request
    rv = self.dispatch_request()
  File "/Library/Frameworks/Python.framework/Versions/3.5/lib/python3.5/site-packages/flask/app.py", line 1461, in dispatch_request
    return self.view_functions[rule.endpoint](**req.view_args)
  File "/Library/Frameworks/Python.framework/Versions/3.5/lib/python3.5/site-packages/flask_restful/__init__.py", line 477, in wrapper
    resp = resource(*args, **kwargs)
  File "/Library/Frameworks/Python.framework/Versions/3.5/lib/python3.5/site-packages/flask/views.py", line 84, in view
    return self.dispatch_request(*args, **kwargs)
  File "/Library/Frameworks/Python.framework/Versions/3.5/lib/python3.5/site-packages/flask_restful/__init__.py", line 587, in dispatch_request
    resp = meth(*args, **kwargs)
  File "/Users/HwiRiRic/Documents/seoulhang_server/seoulhang_server/app/apis.py", line 581, in get
    SendMail(data)
  File "/Users/HwiRiRic/Documents/seoulhang_server/seoulhang_server/send_mail.py", line 21, in __init__
    self.send_confirm_mail(data)
  File "/Users/HwiRiRic/Documents/seoulhang_server/seoulhang_server/send_mail.py", line 56, in send_confirm_mail
    title = self.get_email_content(lost)[0]
  File "/Users/HwiRiRic/Documents/seoulhang_server/seoulhang_server/send_mail.py", line 24, in get_email_content
    f = open("app/import/find_"+lost+".txt","rb")
FileNotFoundError: [Errno 2] No such file or directory: 'app/import/find_id.txt'
ERROR:tornado.access:500 GET /name/%EC%B5%9C%EC%9A%B4%ED%95%99/email/cwh6272@naver.com (192.168.43.1) 5.30ms
ERROR:tornado.application:Uncaught exception GET /name/%EC%B5%9C%EC%9A%B4%ED%95%99/email/cwh6272@naver.com (192.168.43.1)
HTTPServerRequest(protocol='http', host='192.168.43.34:5000', method='GET', uri='/name/%EC%B5%9C%EC%9A%B4%ED%95%99/email/cwh6272@naver.com', version='HTTP/1.1', remote_ip='192.168.43.1', headers={'Host': '192.168.43.34:5000', 'Connection': 'Keep-Alive', 'Accept-Encoding': 'gzip', 'User-Agent': 'okhttp/3.3.0'})
Traceback (most recent call last):
  File "/Library/Frameworks/Python.framework/Versions/3.5/lib/python3.5/site-packages/tornado/web.py", line 1422, in _execute
    result = self.prepare()
  File "/Library/Frameworks/Python.framework/Versions/3.5/lib/python3.5/site-packages/tornado/web.py", line 2681, in prepare
    self.fallback(self.request)
  File "/Library/Frameworks/Python.framework/Versions/3.5/lib/python3.5/site-packages/tornado/wsgi.py", line 277, in __call__
    WSGIContainer.environ(request), start_response)
  File "/Library/Frameworks/Python.framework/Versions/3.5/lib/python3.5/site-packages/flask/app.py", line 1836, in __call__
    return self.wsgi_app(environ, start_response)
  File "/Library/Frameworks/Python.framework/Versions/3.5/lib/python3.5/site-packages/flask/app.py", line 1820, in wsgi_app
    response = self.make_response(self.handle_exception(e))
  File "/Library/Frameworks/Python.framework/Versions/3.5/lib/python3.5/site-packages/flask_restful/__init__.py", line 271, in error_router
    return original_handler(e)
  File "/Library/Frameworks/Python.framework/Versions/3.5/lib/python3.5/site-packages/flask/app.py", line 1403, in handle_exception
    reraise(exc_type, exc_value, tb)
  File "/Library/Frameworks/Python.framework/Versions/3.5/lib/python3.5/site-packages/flask/_compat.py", line 32, in reraise
    raise value.with_traceback(tb)
  File "/Library/Frameworks/Python.framework/Versions/3.5/lib/python3.5/site-packages/flask/app.py", line 1817, in wsgi_app
    response = self.full_dispatch_request()
  File "/Library/Frameworks/Python.framework/Versions/3.5/lib/python3.5/site-packages/flask/app.py", line 1477, in full_dispatch_request
    rv = self.handle_user_exception(e)
  File "/Library/Frameworks/Python.framework/Versions/3.5/lib/python3.5/site-packages/flask_restful/__init__.py", line 271, in error_router
    return original_handler(e)
  File "/Library/Frameworks/Python.framework/Versions/3.5/lib/python3.5/site-packages/flask/app.py", line 1381, in handle_user_exception
    reraise(exc_type, exc_value, tb)
  File "/Library/Frameworks/Python.framework/Versions/3.5/lib/python3.5/site-packages/flask/_compat.py", line 32, in reraise
    raise value.with_traceback(tb)
  File "/Library/Frameworks/Python.framework/Versions/3.5/lib/python3.5/site-packages/flask/app.py", line 1475, in full_dispatch_request
    rv = self.dispatch_request()
  File "/Library/Frameworks/Python.framework/Versions/3.5/lib/python3.5/site-packages/flask/app.py", line 1461, in dispatch_request
    return self.view_functions[rule.endpoint](**req.view_args)
  File "/Library/Frameworks/Python.framework/Versions/3.5/lib/python3.5/site-packages/flask_restful/__init__.py", line 477, in wrapper
    resp = resource(*args, **kwargs)
  File "/Library/Frameworks/Python.framework/Versions/3.5/lib/python3.5/site-packages/flask/views.py", line 84, in view
    return self.dispatch_request(*args, **kwargs)
  File "/Library/Frameworks/Python.framework/Versions/3.5/lib/python3.5/site-packages/flask_restful/__init__.py", line 587, in dispatch_request
    resp = meth(*args, **kwargs)
  File "/Users/HwiRiRic/Documents/seoulhang_server/seoulhang_server/app/apis.py", line 581, in get
    SendMail(data)
  File "/Users/HwiRiRic/Documents/seoulhang_server/seoulhang_server/send_mail.py", line 21, in __init__
    self.send_confirm_mail(data)
  File "/Users/HwiRiRic/Documents/seoulhang_server/seoulhang_server/send_mail.py", line 56, in send_confirm_mail
    title = self.get_email_content(lost)[0]
  File "/Users/HwiRiRic/Documents/seoulhang_server/seoulhang_server/send_mail.py", line 24, in get_email_content
    f = open("app/import/find_"+lost+".txt","rb")
FileNotFoundError: [Errno 2] No such file or directory: 'app/import/find_id.txt'
ERROR:tornado.access:500 GET /name/%EC%B5%9C%EC%9A%B4%ED%95%99/email/cwh6272@naver.com (192.168.43.1) 6.22ms
ERROR:tornado.application:Uncaught exception GET /name/%EC%B5%9C%EC%9A%B4%ED%95%99/email/cwh6272@naver.com (192.168.43.1)
HTTPServerRequest(protocol='http', host='192.168.43.34:5000', method='GET', uri='/name/%EC%B5%9C%EC%9A%B4%ED%95%99/email/cwh6272@naver.com', version='HTTP/1.1', remote_ip='192.168.43.1', headers={'Host': '192.168.43.34:5000', 'Connection': 'Keep-Alive', 'Accept-Encoding': 'gzip', 'User-Agent': 'okhttp/3.3.0'})
Traceback (most recent call last):
  File "/Library/Frameworks/Python.framework/Versions/3.5/lib/python3.5/site-packages/tornado/web.py", line 1422, in _execute
    result = self.prepare()
  File "/Library/Frameworks/Python.framework/Versions/3.5/lib/python3.5/site-packages/tornado/web.py", line 2681, in prepare
    self.fallback(self.request)
  File "/Library/Frameworks/Python.framework/Versions/3.5/lib/python3.5/site-packages/tornado/wsgi.py", line 277, in __call__
    WSGIContainer.environ(request), start_response)
  File "/Library/Frameworks/Python.framework/Versions/3.5/lib/python3.5/site-packages/flask/app.py", line 1836, in __call__
    return self.wsgi_app(environ, start_response)
  File "/Library/Frameworks/Python.framework/Versions/3.5/lib/python3.5/site-packages/flask/app.py", line 1820, in wsgi_app
    response = self.make_response(self.handle_exception(e))
  File "/Library/Frameworks/Python.framework/Versions/3.5/lib/python3.5/site-packages/flask_restful/__init__.py", line 271, in error_router
    return original_handler(e)
  File "/Library/Frameworks/Python.framework/Versions/3.5/lib/python3.5/site-packages/flask/app.py", line 1403, in handle_exception
    reraise(exc_type, exc_value, tb)
  File "/Library/Frameworks/Python.framework/Versions/3.5/lib/python3.5/site-packages/flask/_compat.py", line 32, in reraise
    raise value.with_traceback(tb)
  File "/Library/Frameworks/Python.framework/Versions/3.5/lib/python3.5/site-packages/flask/app.py", line 1817, in wsgi_app
    response = self.full_dispatch_request()
  File "/Library/Frameworks/Python.framework/Versions/3.5/lib/python3.5/site-packages/flask/app.py", line 1477, in full_dispatch_request
    rv = self.handle_user_exception(e)
  File "/Library/Frameworks/Python.framework/Versions/3.5/lib/python3.5/site-packages/flask_restful/__init__.py", line 271, in error_router
    return original_handler(e)
  File "/Library/Frameworks/Python.framework/Versions/3.5/lib/python3.5/site-packages/flask/app.py", line 1381, in handle_user_exception
    reraise(exc_type, exc_value, tb)
  File "/Library/Frameworks/Python.framework/Versions/3.5/lib/python3.5/site-packages/flask/_compat.py", line 32, in reraise
    raise value.with_traceback(tb)
  File "/Library/Frameworks/Python.framework/Versions/3.5/lib/python3.5/site-packages/flask/app.py", line 1475, in full_dispatch_request
    rv = self.dispatch_request()
  File "/Library/Frameworks/Python.framework/Versions/3.5/lib/python3.5/site-packages/flask/app.py", line 1461, in dispatch_request
    return self.view_functions[rule.endpoint](**req.view_args)
  File "/Library/Frameworks/Python.framework/Versions/3.5/lib/python3.5/site-packages/flask_restful/__init__.py", line 477, in wrapper
    resp = resource(*args, **kwargs)
  File "/Library/Frameworks/Python.framework/Versions/3.5/lib/python3.5/site-packages/flask/views.py", line 84, in view
    return self.dispatch_request(*args, **kwargs)
  File "/Library/Frameworks/Python.framework/Versions/3.5/lib/python3.5/site-packages/flask_restful/__init__.py", line 587, in dispatch_request
    resp = meth(*args, **kwargs)
  File "/Users/HwiRiRic/Documents/seoulhang_server/seoulhang_server/app/apis.py", line 581, in get
    SendMail(data)
  File "/Users/HwiRiRic/Documents/seoulhang_server/seoulhang_server/send_mail.py", line 21, in __init__
    self.send_confirm_mail(data)
  File "/Users/HwiRiRic/Documents/seoulhang_server/seoulhang_server/send_mail.py", line 56, in send_confirm_mail
    title = self.get_email_content(lost)[0]
  File "/Users/HwiRiRic/Documents/seoulhang_server/seoulhang_server/send_mail.py", line 24, in get_email_content
    f = open("app/import/find_"+lost+".txt","rb")
FileNotFoundError: [Errno 2] No such file or directory: 'app/import/find_id.txt'
ERROR:tornado.access:500 GET /name/%EC%B5%9C%EC%9A%B4%ED%95%99/email/cwh6272@naver.com (192.168.43.1) 5.98ms
ERROR:tornado.application:Uncaught exception GET /name/%EC%B5%9C%EC%9A%B4%ED%95%99/email/cwh6272@naver.com (192.168.43.1)
HTTPServerRequest(protocol='http', host='192.168.43.34:5000', method='GET', uri='/name/%EC%B5%9C%EC%9A%B4%ED%95%99/email/cwh6272@naver.com', version='HTTP/1.1', remote_ip='192.168.43.1', headers={'Host': '192.168.43.34:5000', 'Connection': 'Keep-Alive', 'Accept-Encoding': 'gzip', 'User-Agent': 'okhttp/3.3.0'})
Traceback (most recent call last):
  File "/Library/Frameworks/Python.framework/Versions/3.5/lib/python3.5/site-packages/tornado/web.py", line 1422, in _execute
    result = self.prepare()
  File "/Library/Frameworks/Python.framework/Versions/3.5/lib/python3.5/site-packages/tornado/web.py", line 2681, in prepare
    self.fallback(self.request)
  File "/Library/Frameworks/Python.framework/Versions/3.5/lib/python3.5/site-packages/tornado/wsgi.py", line 277, in __call__
    WSGIContainer.environ(request), start_response)
  File "/Library/Frameworks/Python.framework/Versions/3.5/lib/python3.5/site-packages/flask/app.py", line 1836, in __call__
    return self.wsgi_app(environ, start_response)
  File "/Library/Frameworks/Python.framework/Versions/3.5/lib/python3.5/site-packages/flask/app.py", line 1820, in wsgi_app
    response = self.make_response(self.handle_exception(e))
  File "/Library/Frameworks/Python.framework/Versions/3.5/lib/python3.5/site-packages/flask_restful/__init__.py", line 271, in error_router
    return original_handler(e)
  File "/Library/Frameworks/Python.framework/Versions/3.5/lib/python3.5/site-packages/flask/app.py", line 1403, in handle_exception
    reraise(exc_type, exc_value, tb)
  File "/Library/Frameworks/Python.framework/Versions/3.5/lib/python3.5/site-packages/flask/_compat.py", line 32, in reraise
    raise value.with_traceback(tb)
  File "/Library/Frameworks/Python.framework/Versions/3.5/lib/python3.5/site-packages/flask/app.py", line 1817, in wsgi_app
    response = self.full_dispatch_request()
  File "/Library/Frameworks/Python.framework/Versions/3.5/lib/python3.5/site-packages/flask/app.py", line 1477, in full_dispatch_request
    rv = self.handle_user_exception(e)
  File "/Library/Frameworks/Python.framework/Versions/3.5/lib/python3.5/site-packages/flask_restful/__init__.py", line 271, in error_router
    return original_handler(e)
  File "/Library/Frameworks/Python.framework/Versions/3.5/lib/python3.5/site-packages/flask/app.py", line 1381, in handle_user_exception
    reraise(exc_type, exc_value, tb)
  File "/Library/Frameworks/Python.framework/Versions/3.5/lib/python3.5/site-packages/flask/_compat.py", line 32, in reraise
    raise value.with_traceback(tb)
  File "/Library/Frameworks/Python.framework/Versions/3.5/lib/python3.5/site-packages/flask/app.py", line 1475, in full_dispatch_request
    rv = self.dispatch_request()
  File "/Library/Frameworks/Python.framework/Versions/3.5/lib/python3.5/site-packages/flask/app.py", line 1461, in dispatch_request
    return self.view_functions[rule.endpoint](**req.view_args)
  File "/Library/Frameworks/Python.framework/Versions/3.5/lib/python3.5/site-packages/flask_restful/__init__.py", line 477, in wrapper
    resp = resource(*args, **kwargs)
  File "/Library/Frameworks/Python.framework/Versions/3.5/lib/python3.5/site-packages/flask/views.py", line 84, in view
    return self.dispatch_request(*args, **kwargs)
  File "/Library/Frameworks/Python.framework/Versions/3.5/lib/python3.5/site-packages/flask_restful/__init__.py", line 587, in dispatch_request
    resp = meth(*args, **kwargs)
  File "/Users/HwiRiRic/Documents/seoulhang_server/seoulhang_server/app/apis.py", line 581, in get
    SendMail(data)
  File "/Users/HwiRiRic/Documents/seoulhang_server/seoulhang_server/send_mail.py", line 21, in __init__
    self.send_confirm_mail(data)
  File "/Users/HwiRiRic/Documents/seoulhang_server/seoulhang_server/send_mail.py", line 56, in send_confirm_mail
    title = self.get_email_content(lost)[0]
  File "/Users/HwiRiRic/Documents/seoulhang_server/seoulhang_server/send_mail.py", line 24, in get_email_content
    f = open("app/import/find_"+lost+".txt","rb")
FileNotFoundError: [Errno 2] No such file or directory: 'app/import/find_id.txt'
ERROR:tornado.access:500 GET /name/%EC%B5%9C%EC%9A%B4%ED%95%99/email/cwh6272@naver.com (192.168.43.1) 5.58ms
ERROR:tornado.application:Uncaught exception GET /name/%EC%B5%9C%EC%9A%B4%ED%95%99/email/cwh6272@naver.com (192.168.43.1)
HTTPServerRequest(protocol='http', host='192.168.43.34:5000', method='GET', uri='/name/%EC%B5%9C%EC%9A%B4%ED%95%99/email/cwh6272@naver.com', version='HTTP/1.1', remote_ip='192.168.43.1', headers={'Host': '192.168.43.34:5000', 'Connection': 'Keep-Alive', 'Accept-Encoding': 'gzip', 'User-Agent': 'okhttp/3.3.0'})
Traceback (most recent call last):
  File "/Library/Frameworks/Python.framework/Versions/3.5/lib/python3.5/site-packages/tornado/web.py", line 1422, in _execute
    result = self.prepare()
  File "/Library/Frameworks/Python.framework/Versions/3.5/lib/python3.5/site-packages/tornado/web.py", line 2681, in prepare
    self.fallback(self.request)
  File "/Library/Frameworks/Python.framework/Versions/3.5/lib/python3.5/site-packages/tornado/wsgi.py", line 277, in __call__
    WSGIContainer.environ(request), start_response)
  File "/Library/Frameworks/Python.framework/Versions/3.5/lib/python3.5/site-packages/flask/app.py", line 1836, in __call__
    return self.wsgi_app(environ, start_response)
  File "/Library/Frameworks/Python.framework/Versions/3.5/lib/python3.5/site-packages/flask/app.py", line 1820, in wsgi_app
    response = self.make_response(self.handle_exception(e))
  File "/Library/Frameworks/Python.framework/Versions/3.5/lib/python3.5/site-packages/flask_restful/__init__.py", line 271, in error_router
    return original_handler(e)
  File "/Library/Frameworks/Python.framework/Versions/3.5/lib/python3.5/site-packages/flask/app.py", line 1403, in handle_exception
    reraise(exc_type, exc_value, tb)
  File "/Library/Frameworks/Python.framework/Versions/3.5/lib/python3.5/site-packages/flask/_compat.py", line 32, in reraise
    raise value.with_traceback(tb)
  File "/Library/Frameworks/Python.framework/Versions/3.5/lib/python3.5/site-packages/flask/app.py", line 1817, in wsgi_app
    response = self.full_dispatch_request()
  File "/Library/Frameworks/Python.framework/Versions/3.5/lib/python3.5/site-packages/flask/app.py", line 1477, in full_dispatch_request
    rv = self.handle_user_exception(e)
  File "/Library/Frameworks/Python.framework/Versions/3.5/lib/python3.5/site-packages/flask_restful/__init__.py", line 271, in error_router
    return original_handler(e)
  File "/Library/Frameworks/Python.framework/Versions/3.5/lib/python3.5/site-packages/flask/app.py", line 1381, in handle_user_exception
    reraise(exc_type, exc_value, tb)
  File "/Library/Frameworks/Python.framework/Versions/3.5/lib/python3.5/site-packages/flask/_compat.py", line 32, in reraise
    raise value.with_traceback(tb)
  File "/Library/Frameworks/Python.framework/Versions/3.5/lib/python3.5/site-packages/flask/app.py", line 1475, in full_dispatch_request
    rv = self.dispatch_request()
  File "/Library/Frameworks/Python.framework/Versions/3.5/lib/python3.5/site-packages/flask/app.py", line 1461, in dispatch_request
    return self.view_functions[rule.endpoint](**req.view_args)
  File "/Library/Frameworks/Python.framework/Versions/3.5/lib/python3.5/site-packages/flask_restful/__init__.py", line 477, in wrapper
    resp = resource(*args, **kwargs)
  File "/Library/Frameworks/Python.framework/Versions/3.5/lib/python3.5/site-packages/flask/views.py", line 84, in view
    return self.dispatch_request(*args, **kwargs)
  File "/Library/Frameworks/Python.framework/Versions/3.5/lib/python3.5/site-packages/flask_restful/__init__.py", line 587, in dispatch_request
    resp = meth(*args, **kwargs)
  File "/Users/HwiRiRic/Documents/seoulhang_server/seoulhang_server/app/apis.py", line 581, in get
    SendMail(data)
  File "/Users/HwiRiRic/Documents/seoulhang_server/seoulhang_server/send_mail.py", line 21, in __init__
    self.send_confirm_mail(data)
  File "/Users/HwiRiRic/Documents/seoulhang_server/seoulhang_server/send_mail.py", line 56, in send_confirm_mail
    title = self.get_email_content(lost)[0]
  File "/Users/HwiRiRic/Documents/seoulhang_server/seoulhang_server/send_mail.py", line 24, in get_email_content
    f = open("app/import/find_"+lost+".txt","rb")
FileNotFoundError: [Errno 2] No such file or directory: 'app/import/find_id.txt'
ERROR:tornado.access:500 GET /name/%EC%B5%9C%EC%9A%B4%ED%95%99/email/cwh6272@naver.com (192.168.43.1) 5.38ms
ERROR:tornado.application:Uncaught exception GET /name/%EC%B5%9C%EC%9A%B4%ED%95%99/email/cwh6272@naver.com (192.168.43.1)
HTTPServerRequest(protocol='http', host='192.168.43.34:5000', method='GET', uri='/name/%EC%B5%9C%EC%9A%B4%ED%95%99/email/cwh6272@naver.com', version='HTTP/1.1', remote_ip='192.168.43.1', headers={'Host': '192.168.43.34:5000', 'Connection': 'Keep-Alive', 'Accept-Encoding': 'gzip', 'User-Agent': 'okhttp/3.3.0'})
Traceback (most recent call last):
  File "/Library/Frameworks/Python.framework/Versions/3.5/lib/python3.5/site-packages/tornado/web.py", line 1422, in _execute
    result = self.prepare()
  File "/Library/Frameworks/Python.framework/Versions/3.5/lib/python3.5/site-packages/tornado/web.py", line 2681, in prepare
    self.fallback(self.request)
  File "/Library/Frameworks/Python.framework/Versions/3.5/lib/python3.5/site-packages/tornado/wsgi.py", line 277, in __call__
    WSGIContainer.environ(request), start_response)
  File "/Library/Frameworks/Python.framework/Versions/3.5/lib/python3.5/site-packages/flask/app.py", line 1836, in __call__
    return self.wsgi_app(environ, start_response)
  File "/Library/Frameworks/Python.framework/Versions/3.5/lib/python3.5/site-packages/flask/app.py", line 1820, in wsgi_app
    response = self.make_response(self.handle_exception(e))
  File "/Library/Frameworks/Python.framework/Versions/3.5/lib/python3.5/site-packages/flask_restful/__init__.py", line 271, in error_router
    return original_handler(e)
  File "/Library/Frameworks/Python.framework/Versions/3.5/lib/python3.5/site-packages/flask/app.py", line 1403, in handle_exception
    reraise(exc_type, exc_value, tb)
  File "/Library/Frameworks/Python.framework/Versions/3.5/lib/python3.5/site-packages/flask/_compat.py", line 32, in reraise
    raise value.with_traceback(tb)
  File "/Library/Frameworks/Python.framework/Versions/3.5/lib/python3.5/site-packages/flask/app.py", line 1817, in wsgi_app
    response = self.full_dispatch_request()
  File "/Library/Frameworks/Python.framework/Versions/3.5/lib/python3.5/site-packages/flask/app.py", line 1477, in full_dispatch_request
    rv = self.handle_user_exception(e)
  File "/Library/Frameworks/Python.framework/Versions/3.5/lib/python3.5/site-packages/flask_restful/__init__.py", line 271, in error_router
    return original_handler(e)
  File "/Library/Frameworks/Python.framework/Versions/3.5/lib/python3.5/site-packages/flask/app.py", line 1381, in handle_user_exception
    reraise(exc_type, exc_value, tb)
  File "/Library/Frameworks/Python.framework/Versions/3.5/lib/python3.5/site-packages/flask/_compat.py", line 32, in reraise
    raise value.with_traceback(tb)
  File "/Library/Frameworks/Python.framework/Versions/3.5/lib/python3.5/site-packages/flask/app.py", line 1475, in full_dispatch_request
    rv = self.dispatch_request()
  File "/Library/Frameworks/Python.framework/Versions/3.5/lib/python3.5/site-packages/flask/app.py", line 1461, in dispatch_request
    return self.view_functions[rule.endpoint](**req.view_args)
  File "/Library/Frameworks/Python.framework/Versions/3.5/lib/python3.5/site-packages/flask_restful/__init__.py", line 477, in wrapper
    resp = resource(*args, **kwargs)
  File "/Library/Frameworks/Python.framework/Versions/3.5/lib/python3.5/site-packages/flask/views.py", line 84, in view
    return self.dispatch_request(*args, **kwargs)
  File "/Library/Frameworks/Python.framework/Versions/3.5/lib/python3.5/site-packages/flask_restful/__init__.py", line 587, in dispatch_request
    resp = meth(*args, **kwargs)
  File "/Users/HwiRiRic/Documents/seoulhang_server/seoulhang_server/app/apis.py", line 581, in get
    SendMail(data)
  File "/Users/HwiRiRic/Documents/seoulhang_server/seoulhang_server/send_mail.py", line 21, in __init__
    self.send_confirm_mail(data)
  File "/Users/HwiRiRic/Documents/seoulhang_server/seoulhang_server/send_mail.py", line 56, in send_confirm_mail
    title = self.get_email_content(lost)[0]
  File "/Users/HwiRiRic/Documents/seoulhang_server/seoulhang_server/send_mail.py", line 24, in get_email_content
    f = open("app/import/find_"+lost+".txt","rb")
FileNotFoundError: [Errno 2] No such file or directory: 'app/import/find_id.txt'
ERROR:tornado.access:500 GET /name/%EC%B5%9C%EC%9A%B4%ED%95%99/email/cwh6272@naver.com (192.168.43.1) 6.66ms
ERROR:tornado.application:Uncaught exception GET /name/%EC%B5%9C%EC%9A%B4%ED%95%99/email/cwh6272@naver.com (192.168.43.1)
HTTPServerRequest(protocol='http', host='192.168.43.34:5000', method='GET', uri='/name/%EC%B5%9C%EC%9A%B4%ED%95%99/email/cwh6272@naver.com', version='HTTP/1.1', remote_ip='192.168.43.1', headers={'Host': '192.168.43.34:5000', 'Connection': 'Keep-Alive', 'Accept-Encoding': 'gzip', 'User-Agent': 'okhttp/3.3.0'})
Traceback (most recent call last):
  File "/Library/Frameworks/Python.framework/Versions/3.5/lib/python3.5/site-packages/tornado/web.py", line 1422, in _execute
    result = self.prepare()
  File "/Library/Frameworks/Python.framework/Versions/3.5/lib/python3.5/site-packages/tornado/web.py", line 2681, in prepare
    self.fallback(self.request)
  File "/Library/Frameworks/Python.framework/Versions/3.5/lib/python3.5/site-packages/tornado/wsgi.py", line 277, in __call__
    WSGIContainer.environ(request), start_response)
  File "/Library/Frameworks/Python.framework/Versions/3.5/lib/python3.5/site-packages/flask/app.py", line 1836, in __call__
    return self.wsgi_app(environ, start_response)
  File "/Library/Frameworks/Python.framework/Versions/3.5/lib/python3.5/site-packages/flask/app.py", line 1820, in wsgi_app
    response = self.make_response(self.handle_exception(e))
  File "/Library/Frameworks/Python.framework/Versions/3.5/lib/python3.5/site-packages/flask_restful/__init__.py", line 271, in error_router
    return original_handler(e)
  File "/Library/Frameworks/Python.framework/Versions/3.5/lib/python3.5/site-packages/flask/app.py", line 1403, in handle_exception
    reraise(exc_type, exc_value, tb)
  File "/Library/Frameworks/Python.framework/Versions/3.5/lib/python3.5/site-packages/flask/_compat.py", line 32, in reraise
    raise value.with_traceback(tb)
  File "/Library/Frameworks/Python.framework/Versions/3.5/lib/python3.5/site-packages/flask/app.py", line 1817, in wsgi_app
    response = self.full_dispatch_request()
  File "/Library/Frameworks/Python.framework/Versions/3.5/lib/python3.5/site-packages/flask/app.py", line 1477, in full_dispatch_request
    rv = self.handle_user_exception(e)
  File "/Library/Frameworks/Python.framework/Versions/3.5/lib/python3.5/site-packages/flask_restful/__init__.py", line 271, in error_router
    return original_handler(e)
  File "/Library/Frameworks/Python.framework/Versions/3.5/lib/python3.5/site-packages/flask/app.py", line 1381, in handle_user_exception
    reraise(exc_type, exc_value, tb)
  File "/Library/Frameworks/Python.framework/Versions/3.5/lib/python3.5/site-packages/flask/_compat.py", line 32, in reraise
    raise value.with_traceback(tb)
  File "/Library/Frameworks/Python.framework/Versions/3.5/lib/python3.5/site-packages/flask/app.py", line 1475, in full_dispatch_request
    rv = self.dispatch_request()
  File "/Library/Frameworks/Python.framework/Versions/3.5/lib/python3.5/site-packages/flask/app.py", line 1461, in dispatch_request
    return self.view_functions[rule.endpoint](**req.view_args)
  File "/Library/Frameworks/Python.framework/Versions/3.5/lib/python3.5/site-packages/flask_restful/__init__.py", line 477, in wrapper
    resp = resource(*args, **kwargs)
  File "/Library/Frameworks/Python.framework/Versions/3.5/lib/python3.5/site-packages/flask/views.py", line 84, in view
    return self.dispatch_request(*args, **kwargs)
  File "/Library/Frameworks/Python.framework/Versions/3.5/lib/python3.5/site-packages/flask_restful/__init__.py", line 587, in dispatch_request
    resp = meth(*args, **kwargs)
  File "/Users/HwiRiRic/Documents/seoulhang_server/seoulhang_server/app/apis.py", line 581, in get
    SendMail(data)
  File "/Users/HwiRiRic/Documents/seoulhang_server/seoulhang_server/send_mail.py", line 21, in __init__
    self.send_confirm_mail(data)
  File "/Users/HwiRiRic/Documents/seoulhang_server/seoulhang_server/send_mail.py", line 56, in send_confirm_mail
    title = self.get_email_content(lost)[0]
  File "/Users/HwiRiRic/Documents/seoulhang_server/seoulhang_server/send_mail.py", line 24, in get_email_content
    f = open("app/import/find_"+lost+".txt","rb")
FileNotFoundError: [Errno 2] No such file or directory: 'app/import/find_id.txt'
ERROR:tornado.access:500 GET /name/%EC%B5%9C%EC%9A%B4%ED%95%99/email/cwh6272@naver.com (192.168.43.1) 5.81ms
ERROR:tornado.application:Uncaught exception GET /name/%EC%B5%9C%EC%9A%B4%ED%95%99/email/cwh6272@naver.com (192.168.43.1)
HTTPServerRequest(protocol='http', host='192.168.43.34:5000', method='GET', uri='/name/%EC%B5%9C%EC%9A%B4%ED%95%99/email/cwh6272@naver.com', version='HTTP/1.1', remote_ip='192.168.43.1', headers={'Host': '192.168.43.34:5000', 'Connection': 'Keep-Alive', 'Accept-Encoding': 'gzip', 'User-Agent': 'okhttp/3.3.0'})
Traceback (most recent call last):
  File "/Library/Frameworks/Python.framework/Versions/3.5/lib/python3.5/site-packages/tornado/web.py", line 1422, in _execute
    result = self.prepare()
  File "/Library/Frameworks/Python.framework/Versions/3.5/lib/python3.5/site-packages/tornado/web.py", line 2681, in prepare
    self.fallback(self.request)
  File "/Library/Frameworks/Python.framework/Versions/3.5/lib/python3.5/site-packages/tornado/wsgi.py", line 277, in __call__
    WSGIContainer.environ(request), start_response)
  File "/Library/Frameworks/Python.framework/Versions/3.5/lib/python3.5/site-packages/flask/app.py", line 1836, in __call__
    return self.wsgi_app(environ, start_response)
  File "/Library/Frameworks/Python.framework/Versions/3.5/lib/python3.5/site-packages/flask/app.py", line 1820, in wsgi_app
    response = self.make_response(self.handle_exception(e))
  File "/Library/Frameworks/Python.framework/Versions/3.5/lib/python3.5/site-packages/flask_restful/__init__.py", line 271, in error_router
    return original_handler(e)
  File "/Library/Frameworks/Python.framework/Versions/3.5/lib/python3.5/site-packages/flask/app.py", line 1403, in handle_exception
    reraise(exc_type, exc_value, tb)
  File "/Library/Frameworks/Python.framework/Versions/3.5/lib/python3.5/site-packages/flask/_compat.py", line 32, in reraise
    raise value.with_traceback(tb)
  File "/Library/Frameworks/Python.framework/Versions/3.5/lib/python3.5/site-packages/flask/app.py", line 1817, in wsgi_app
    response = self.full_dispatch_request()
  File "/Library/Frameworks/Python.framework/Versions/3.5/lib/python3.5/site-packages/flask/app.py", line 1477, in full_dispatch_request
    rv = self.handle_user_exception(e)
  File "/Library/Frameworks/Python.framework/Versions/3.5/lib/python3.5/site-packages/flask_restful/__init__.py", line 271, in error_router
    return original_handler(e)
  File "/Library/Frameworks/Python.framework/Versions/3.5/lib/python3.5/site-packages/flask/app.py", line 1381, in handle_user_exception
    reraise(exc_type, exc_value, tb)
  File "/Library/Frameworks/Python.framework/Versions/3.5/lib/python3.5/site-packages/flask/_compat.py", line 32, in reraise
    raise value.with_traceback(tb)
  File "/Library/Frameworks/Python.framework/Versions/3.5/lib/python3.5/site-packages/flask/app.py", line 1475, in full_dispatch_request
    rv = self.dispatch_request()
  File "/Library/Frameworks/Python.framework/Versions/3.5/lib/python3.5/site-packages/flask/app.py", line 1461, in dispatch_request
    return self.view_functions[rule.endpoint](**req.view_args)
  File "/Library/Frameworks/Python.framework/Versions/3.5/lib/python3.5/site-packages/flask_restful/__init__.py", line 477, in wrapper
    resp = resource(*args, **kwargs)
  File "/Library/Frameworks/Python.framework/Versions/3.5/lib/python3.5/site-packages/flask/views.py", line 84, in view
    return self.dispatch_request(*args, **kwargs)
  File "/Library/Frameworks/Python.framework/Versions/3.5/lib/python3.5/site-packages/flask_restful/__init__.py", line 587, in dispatch_request
    resp = meth(*args, **kwargs)
  File "/Users/HwiRiRic/Documents/seoulhang_server/seoulhang_server/app/apis.py", line 581, in get
    SendMail(data)
  File "/Users/HwiRiRic/Documents/seoulhang_server/seoulhang_server/send_mail.py", line 21, in __init__
    self.send_confirm_mail(data)
  File "/Users/HwiRiRic/Documents/seoulhang_server/seoulhang_server/send_mail.py", line 56, in send_confirm_mail
    title = self.get_email_content(lost)[0]
  File "/Users/HwiRiRic/Documents/seoulhang_server/seoulhang_server/send_mail.py", line 24, in get_email_content
    f = open("app/import/find_"+lost+".txt","rb")
FileNotFoundError: [Errno 2] No such file or directory: 'app/import/find_id.txt'
ERROR:tornado.access:500 GET /name/%EC%B5%9C%EC%9A%B4%ED%95%99/email/cwh6272@naver.com (192.168.43.1) 5.61ms
ERROR:tornado.application:Uncaught exception GET /name/%EC%B5%9C%EC%9A%B4%ED%95%99/email/cwh6272@naver.com (192.168.43.1)
HTTPServerRequest(protocol='http', host='192.168.43.34:5000', method='GET', uri='/name/%EC%B5%9C%EC%9A%B4%ED%95%99/email/cwh6272@naver.com', version='HTTP/1.1', remote_ip='192.168.43.1', headers={'Host': '192.168.43.34:5000', 'Connection': 'Keep-Alive', 'Accept-Encoding': 'gzip', 'User-Agent': 'okhttp/3.3.0'})
Traceback (most recent call last):
  File "/Library/Frameworks/Python.framework/Versions/3.5/lib/python3.5/site-packages/tornado/web.py", line 1422, in _execute
    result = self.prepare()
  File "/Library/Frameworks/Python.framework/Versions/3.5/lib/python3.5/site-packages/tornado/web.py", line 2681, in prepare
    self.fallback(self.request)
  File "/Library/Frameworks/Python.framework/Versions/3.5/lib/python3.5/site-packages/tornado/wsgi.py", line 277, in __call__
    WSGIContainer.environ(request), start_response)
  File "/Library/Frameworks/Python.framework/Versions/3.5/lib/python3.5/site-packages/flask/app.py", line 1836, in __call__
    return self.wsgi_app(environ, start_response)
  File "/Library/Frameworks/Python.framework/Versions/3.5/lib/python3.5/site-packages/flask/app.py", line 1820, in wsgi_app
    response = self.make_response(self.handle_exception(e))
  File "/Library/Frameworks/Python.framework/Versions/3.5/lib/python3.5/site-packages/flask_restful/__init__.py", line 271, in error_router
    return original_handler(e)
  File "/Library/Frameworks/Python.framework/Versions/3.5/lib/python3.5/site-packages/flask/app.py", line 1403, in handle_exception
    reraise(exc_type, exc_value, tb)
  File "/Library/Frameworks/Python.framework/Versions/3.5/lib/python3.5/site-packages/flask/_compat.py", line 32, in reraise
    raise value.with_traceback(tb)
  File "/Library/Frameworks/Python.framework/Versions/3.5/lib/python3.5/site-packages/flask/app.py", line 1817, in wsgi_app
    response = self.full_dispatch_request()
  File "/Library/Frameworks/Python.framework/Versions/3.5/lib/python3.5/site-packages/flask/app.py", line 1477, in full_dispatch_request
    rv = self.handle_user_exception(e)
  File "/Library/Frameworks/Python.framework/Versions/3.5/lib/python3.5/site-packages/flask_restful/__init__.py", line 271, in error_router
    return original_handler(e)
  File "/Library/Frameworks/Python.framework/Versions/3.5/lib/python3.5/site-packages/flask/app.py", line 1381, in handle_user_exception
    reraise(exc_type, exc_value, tb)
  File "/Library/Frameworks/Python.framework/Versions/3.5/lib/python3.5/site-packages/flask/_compat.py", line 32, in reraise
    raise value.with_traceback(tb)
  File "/Library/Frameworks/Python.framework/Versions/3.5/lib/python3.5/site-packages/flask/app.py", line 1475, in full_dispatch_request
    rv = self.dispatch_request()
  File "/Library/Frameworks/Python.framework/Versions/3.5/lib/python3.5/site-packages/flask/app.py", line 1461, in dispatch_request
    return self.view_functions[rule.endpoint](**req.view_args)
  File "/Library/Frameworks/Python.framework/Versions/3.5/lib/python3.5/site-packages/flask_restful/__init__.py", line 477, in wrapper
    resp = resource(*args, **kwargs)
  File "/Library/Frameworks/Python.framework/Versions/3.5/lib/python3.5/site-packages/flask/views.py", line 84, in view
    return self.dispatch_request(*args, **kwargs)
  File "/Library/Frameworks/Python.framework/Versions/3.5/lib/python3.5/site-packages/flask_restful/__init__.py", line 587, in dispatch_request
    resp = meth(*args, **kwargs)
  File "/Users/HwiRiRic/Documents/seoulhang_server/seoulhang_server/app/apis.py", line 581, in get
    SendMail(data)
  File "/Users/HwiRiRic/Documents/seoulhang_server/seoulhang_server/send_mail.py", line 21, in __init__
    self.send_confirm_mail(data)
  File "/Users/HwiRiRic/Documents/seoulhang_server/seoulhang_server/send_mail.py", line 56, in send_confirm_mail
    title = self.get_email_content(lost)[0]
  File "/Users/HwiRiRic/Documents/seoulhang_server/seoulhang_server/send_mail.py", line 24, in get_email_content
    f = open("app/import/find_"+lost+".txt","rb")
FileNotFoundError: [Errno 2] No such file or directory: 'app/import/find_id.txt'
ERROR:tornado.access:500 GET /name/%EC%B5%9C%EC%9A%B4%ED%95%99/email/cwh6272@naver.com (192.168.43.1) 5.46ms
INFO:tornado.access:200 GET /players/qpqp/password/qpqp (192.168.43.1) 8.83ms
INFO:tornado.access:200 GET /setting_language/qpqp/language/1 (192.168.43.1) 10.32ms
INFO:tornado.access:200 GET /finish_player/qpqp (192.168.43.1) 6.50ms
INFO:tornado.access:200 GET /start_player/qpqp (192.168.43.1) 5.33ms
INFO:tornado.access:200 GET /finish_player/qpqp (192.168.43.1) 6.05ms
INFO:tornado.access:200 GET /start_player/qpqp (192.168.43.1) 3.36ms
INFO:tornado.access:200 GET /finish_player/qpqp (192.168.43.1) 6.22ms
INFO:tornado.access:200 GET /rate/qpqp (192.168.43.1) 90.63ms
INFO:tornado.access:200 GET /ranking/qpqp (192.168.43.1) 13.86ms
INFO:tornado.access:200 GET /setting_language/qpqp/language/0 (192.168.43.1) 8.26ms
INFO:tornado.access:200 GET /finish_player/qpqp (192.168.43.1) 6.44ms
INFO:tornado.access:200 GET /start_player/qpqp (192.168.43.1) 4.49ms
INFO:tornado.access:200 GET /start_player/qpqp (192.168.43.1) 3.27ms
INFO:tornado.access:200 GET /finish_player/qpqp (192.168.43.1) 6.08ms
INFO:tornado.access:200 GET /finish_player/qpqp (192.168.43.1) 5.19ms
INFO:tornado.access:200 GET /rate/qpqp (192.168.43.1) 100.26ms
INFO:tornado.access:200 GET /ranking/qpqp (192.168.43.1) 26.11ms
ERROR:tornado.application:Uncaught exception GET /name/%EC%B5%9C%EC%9A%B4%ED%95%99/email/cwh6272@naver.com (192.168.43.1)
HTTPServerRequest(protocol='http', host='192.168.43.34:5000', method='GET', uri='/name/%EC%B5%9C%EC%9A%B4%ED%95%99/email/cwh6272@naver.com', version='HTTP/1.1', remote_ip='192.168.43.1', headers={'Host': '192.168.43.34:5000', 'Connection': 'Keep-Alive', 'Accept-Encoding': 'gzip', 'User-Agent': 'okhttp/3.3.0'})
Traceback (most recent call last):
  File "/Library/Frameworks/Python.framework/Versions/3.5/lib/python3.5/site-packages/tornado/web.py", line 1422, in _execute
    result = self.prepare()
  File "/Library/Frameworks/Python.framework/Versions/3.5/lib/python3.5/site-packages/tornado/web.py", line 2681, in prepare
    self.fallback(self.request)
  File "/Library/Frameworks/Python.framework/Versions/3.5/lib/python3.5/site-packages/tornado/wsgi.py", line 277, in __call__
    WSGIContainer.environ(request), start_response)
  File "/Library/Frameworks/Python.framework/Versions/3.5/lib/python3.5/site-packages/flask/app.py", line 1836, in __call__
    return self.wsgi_app(environ, start_response)
  File "/Library/Frameworks/Python.framework/Versions/3.5/lib/python3.5/site-packages/flask/app.py", line 1820, in wsgi_app
    response = self.make_response(self.handle_exception(e))
  File "/Library/Frameworks/Python.framework/Versions/3.5/lib/python3.5/site-packages/flask_restful/__init__.py", line 271, in error_router
    return original_handler(e)
  File "/Library/Frameworks/Python.framework/Versions/3.5/lib/python3.5/site-packages/flask/app.py", line 1403, in handle_exception
    reraise(exc_type, exc_value, tb)
  File "/Library/Frameworks/Python.framework/Versions/3.5/lib/python3.5/site-packages/flask/_compat.py", line 32, in reraise
    raise value.with_traceback(tb)
  File "/Library/Frameworks/Python.framework/Versions/3.5/lib/python3.5/site-packages/flask/app.py", line 1817, in wsgi_app
    response = self.full_dispatch_request()
  File "/Library/Frameworks/Python.framework/Versions/3.5/lib/python3.5/site-packages/flask/app.py", line 1477, in full_dispatch_request
    rv = self.handle_user_exception(e)
  File "/Library/Frameworks/Python.framework/Versions/3.5/lib/python3.5/site-packages/flask_restful/__init__.py", line 271, in error_router
    return original_handler(e)
  File "/Library/Frameworks/Python.framework/Versions/3.5/lib/python3.5/site-packages/flask/app.py", line 1381, in handle_user_exception
    reraise(exc_type, exc_value, tb)
  File "/Library/Frameworks/Python.framework/Versions/3.5/lib/python3.5/site-packages/flask/_compat.py", line 32, in reraise
    raise value.with_traceback(tb)
  File "/Library/Frameworks/Python.framework/Versions/3.5/lib/python3.5/site-packages/flask/app.py", line 1475, in full_dispatch_request
    rv = self.dispatch_request()
  File "/Library/Frameworks/Python.framework/Versions/3.5/lib/python3.5/site-packages/flask/app.py", line 1461, in dispatch_request
    return self.view_functions[rule.endpoint](**req.view_args)
  File "/Library/Frameworks/Python.framework/Versions/3.5/lib/python3.5/site-packages/flask_restful/__init__.py", line 477, in wrapper
    resp = resource(*args, **kwargs)
  File "/Library/Frameworks/Python.framework/Versions/3.5/lib/python3.5/site-packages/flask/views.py", line 84, in view
    return self.dispatch_request(*args, **kwargs)
  File "/Library/Frameworks/Python.framework/Versions/3.5/lib/python3.5/site-packages/flask_restful/__init__.py", line 587, in dispatch_request
    resp = meth(*args, **kwargs)
  File "/Users/HwiRiRic/Documents/seoulhang_server/seoulhang_server/app/apis.py", line 581, in get
    SendMail(data)
  File "/Users/HwiRiRic/Documents/seoulhang_server/seoulhang_server/send_mail.py", line 21, in __init__
    self.send_confirm_mail(data)
  File "/Users/HwiRiRic/Documents/seoulhang_server/seoulhang_server/send_mail.py", line 56, in send_confirm_mail
    title = self.get_email_content(lost)[0]
  File "/Users/HwiRiRic/Documents/seoulhang_server/seoulhang_server/send_mail.py", line 24, in get_email_content
    f = open("app/import/find_"+lost+".txt","rb")
FileNotFoundError: [Errno 2] No such file or directory: 'app/import/find_id.txt'
ERROR:tornado.access:500 GET /name/%EC%B5%9C%EC%9A%B4%ED%95%99/email/cwh6272@naver.com (192.168.43.1) 6.62ms
ERROR:tornado.application:Uncaught exception GET /name/%EC%B5%9C%EC%9A%B4%ED%95%99/email/cwh6272@naver.com (192.168.43.1)
HTTPServerRequest(protocol='http', host='192.168.43.34:5000', method='GET', uri='/name/%EC%B5%9C%EC%9A%B4%ED%95%99/email/cwh6272@naver.com', version='HTTP/1.1', remote_ip='192.168.43.1', headers={'Host': '192.168.43.34:5000', 'Connection': 'Keep-Alive', 'Accept-Encoding': 'gzip', 'User-Agent': 'okhttp/3.3.0'})
Traceback (most recent call last):
  File "/Library/Frameworks/Python.framework/Versions/3.5/lib/python3.5/site-packages/tornado/web.py", line 1422, in _execute
    result = self.prepare()
  File "/Library/Frameworks/Python.framework/Versions/3.5/lib/python3.5/site-packages/tornado/web.py", line 2681, in prepare
    self.fallback(self.request)
  File "/Library/Frameworks/Python.framework/Versions/3.5/lib/python3.5/site-packages/tornado/wsgi.py", line 277, in __call__
    WSGIContainer.environ(request), start_response)
  File "/Library/Frameworks/Python.framework/Versions/3.5/lib/python3.5/site-packages/flask/app.py", line 1836, in __call__
    return self.wsgi_app(environ, start_response)
  File "/Library/Frameworks/Python.framework/Versions/3.5/lib/python3.5/site-packages/flask/app.py", line 1820, in wsgi_app
    response = self.make_response(self.handle_exception(e))
  File "/Library/Frameworks/Python.framework/Versions/3.5/lib/python3.5/site-packages/flask_restful/__init__.py", line 271, in error_router
    return original_handler(e)
  File "/Library/Frameworks/Python.framework/Versions/3.5/lib/python3.5/site-packages/flask/app.py", line 1403, in handle_exception
    reraise(exc_type, exc_value, tb)
  File "/Library/Frameworks/Python.framework/Versions/3.5/lib/python3.5/site-packages/flask/_compat.py", line 32, in reraise
    raise value.with_traceback(tb)
  File "/Library/Frameworks/Python.framework/Versions/3.5/lib/python3.5/site-packages/flask/app.py", line 1817, in wsgi_app
    response = self.full_dispatch_request()
  File "/Library/Frameworks/Python.framework/Versions/3.5/lib/python3.5/site-packages/flask/app.py", line 1477, in full_dispatch_request
    rv = self.handle_user_exception(e)
  File "/Library/Frameworks/Python.framework/Versions/3.5/lib/python3.5/site-packages/flask_restful/__init__.py", line 271, in error_router
    return original_handler(e)
  File "/Library/Frameworks/Python.framework/Versions/3.5/lib/python3.5/site-packages/flask/app.py", line 1381, in handle_user_exception
    reraise(exc_type, exc_value, tb)
  File "/Library/Frameworks/Python.framework/Versions/3.5/lib/python3.5/site-packages/flask/_compat.py", line 32, in reraise
    raise value.with_traceback(tb)
  File "/Library/Frameworks/Python.framework/Versions/3.5/lib/python3.5/site-packages/flask/app.py", line 1475, in full_dispatch_request
    rv = self.dispatch_request()
  File "/Library/Frameworks/Python.framework/Versions/3.5/lib/python3.5/site-packages/flask/app.py", line 1461, in dispatch_request
    return self.view_functions[rule.endpoint](**req.view_args)
  File "/Library/Frameworks/Python.framework/Versions/3.5/lib/python3.5/site-packages/flask_restful/__init__.py", line 477, in wrapper
    resp = resource(*args, **kwargs)
  File "/Library/Frameworks/Python.framework/Versions/3.5/lib/python3.5/site-packages/flask/views.py", line 84, in view
    return self.dispatch_request(*args, **kwargs)
  File "/Library/Frameworks/Python.framework/Versions/3.5/lib/python3.5/site-packages/flask_restful/__init__.py", line 587, in dispatch_request
    resp = meth(*args, **kwargs)
  File "/Users/HwiRiRic/Documents/seoulhang_server/seoulhang_server/app/apis.py", line 581, in get
    SendMail(data)
  File "/Users/HwiRiRic/Documents/seoulhang_server/seoulhang_server/send_mail.py", line 21, in __init__
    self.send_confirm_mail(data)
  File "/Users/HwiRiRic/Documents/seoulhang_server/seoulhang_server/send_mail.py", line 56, in send_confirm_mail
    title = self.get_email_content(lost)[0]
  File "/Users/HwiRiRic/Documents/seoulhang_server/seoulhang_server/send_mail.py", line 24, in get_email_content
    f = open("app/import/find_"+lost+".txt","rb")
FileNotFoundError: [Errno 2] No such file or directory: 'app/import/find_id.txt'
ERROR:tornado.access:500 GET /name/%EC%B5%9C%EC%9A%B4%ED%95%99/email/cwh6272@naver.com (192.168.43.1) 6.52ms
INFO:tornado.access:200 GET /name/%EC%B5%9C%EC%9A%B4%ED%95%99/email/cwh6272@naver.com (192.168.43.1) 5333.12ms
INFO:tornado.access:200 GET /name/%EC%B5%9C%EC%9A%B4%ED%95%99/email/cwh6272@naver.com/id/qpqp (192.168.43.1) 5345.23ms
INFO:tornado.access:204 GET /checkid/qpqp (127.0.0.1) 6.23ms
INFO:tornado.access:204 GET /checkid/qpqp (127.0.0.1) 4.54ms
INFO:tornado.access:204 GET /name/%EC%B5%9C%EC%9A%B4%ED%95%99/email/aaaa (127.0.0.1) 4.46ms
WARNING:tornado.access:404 GET /name/%EC%B5%9C%EC%9A%B4%ED%95%99/email/ (127.0.0.1) 22.11ms
WARNING:tornado.access:404 GET /name/%EC%B5%9C%EC%9A%B4%ED%95%99/email (127.0.0.1) 1.17ms
INFO:tornado.access:204 GET /checkid/qpqp (127.0.0.1) 5.46ms
INFO:tornado.access:200 GET /checkid/qpqpqp (127.0.0.1) 6.55ms
INFO:tornado.access:204 GET /checkid/qpqp (127.0.0.1) 3.74ms
INFO:tornado.access:204 GET /checkid/qpqp (127.0.0.1) 5.01ms
INFO:tornado.access:204 GET /checkid/qpqp (127.0.0.1) 3.74ms
INFO:tornado.access:204 GET /checkid/qpqp (127.0.0.1) 5.11ms
INFO:tornado.general:/Users/HwiRiRic/Documents/seoulhang_server/seoulhang_server/send_mail.py modified; restarting server
